Workbook

Sheet Instructions
B1: FORM 4120SR, CONTROL TESTING TEMPLATE (EXCEL VERSION) — SIGNIFICANT RISK | G1: (3-23)
B2: Note: Changes made during March 2023 were reference updates only; no substantive changes were made. Engagement teams that have already begun using the previous version of the Form are not required to use the new version.
B4: GENERAL INSTRUCTIONS
B6: Purpose
B7: This Form is required to be completed to document our tests and evaluation of the design and operating effectiveness of controls that address a significant risk for which the engagement team has assessed the risk associated with the control as higher for audits performed in accordance with the standards of the PCAOB and the standards of the American Institute of Certified Public Accountants (AICPA) – for AICPA Integrated Audits only. Either this Form or Form 4120S-CRE is required to be completed to document our tests and evaluation of the design and operating effectiveness of controls with a review element that address an accounting estimate when the control addresses a higher risk and the risk associated with the control is higher.
B10: Utilizing this Form
B12: 1) The Executive Summary tab is populated automatically by the separate Control tabs; thus, there are no direct inputs necessary to populate the Executive Summary tab.
B13: 2) The Control tabs are pre-formatted for up to five controls. If you have more than five controls to include in this workbook, the instructions for inserting additional tabs are as follows:
B14: a) Copy the "Template" tab for as many additional tabs as will be needed in the workbook.
B15: - Use an identifier to label the tabs for each control (e.g., client control number).
B16: b) Update the formatting of the Executive Summary tab to capture information from each tab.
B17: - Highlight and copy the area from row 2 to row 36 in column E.
B18: - Select the first empty column in row 2 to the right of the last control in the "Internal Control Dashboard" and paste the information copied in the previous step (be sure to paste formulas and formatting).
... B22: - For any new columns added to the right of the Internal Control Dashboard on the Executive Summary tab, select that column from row 2 to row 36, and find and replace the existing tab name (e.g., "Control 1") with the name of the corresponding tab added in step 2. Note: The find/replace function works well for finding all instances within a column of an old tab name and replacing it with a new tab name. Be sure to select the area you want to perform changes on prior to deciding to "replace all."

Sheet Executive Summary
B1: Internal Control Dashboard
B2: Control ID | E2: ='Control 1'!$C$4 -> Control 1 | F2: ='Control 2'!$C$4 -> Control 2 | G2: ='Control 3'!$C$4 -> Control 3 | H2: ='Control 4'!$C$4 -> Control 4 | I2: ='Control 5'!$C$4 -> Control 5
C3: Risk of Material Misstatement / Risk Associated with the Control | E3: ='Control 1'!$C$170 -> Lower Risk of Material Misstatement - Not Higher Risk Associated with the Control | F3: ='Control 2'!$C$170 -> Lower Risk of Material Misstatement - Not Higher Risk Associated with the Control | G3: ='Control 3'!$C$170 -> Lower Risk of Material Misstatement - Not Higher Risk Associated with the Control | H3: ='Control 4'!$C$170 -> Lower Risk of Material Misstatement - Not Higher Risk Associated with the Control | I3: ='Control 5'!$C$170 -> Lower Risk of Material Misstatement - Not Higher Risk Associated with the Control
B5: Testing Approach | C5: Test and Evaluation of Control Design
C6: Nature | E6: =IF('Control 1'!$I$27="X",'Control 1'!$G$27," ") -> Manual | F6: =IF('Control 2'!$I$27="X",'Control 2'!$G$27," ") | G6: =IF('Control 3'!$I$27="X",'Control 3'!$G$27," ") | H6: =IF('Control 4'!$I$27="X",'Control 4'!$G$27," ") | I6: =IF('Control 5'!$I$27="X",'Control 5'!$G$27," ") -> Manual
E7: =IF('Control 1'!$K$27="X",'Control 1'!$J$27," ") | F7: =IF('Control 2'!$K$27="X",'Control 2'!$J$27," ") -> Automated | G7: =IF('Control 3'!$K$27="X",'Control 3'!$J$27," ") -> Automated | H7: =IF('Control 4'!$K$27="X",'Control 4'!$J$27," ") -> Automated | I7: =IF('Control 5'!$K$27="X",'Control 5'!$J$27," ")
C8: Approach | E8: =IF('Control 1'!$I$29="X",'Control 1'!$G$29," ") -> Preventive | F8: =IF('Control 2'!$I$29="X",'Control 2'!$G$29," ") | G8: =IF('Control 3'!$I$29="X",'Control 3'!$G$29," ") -> Preventive | H8: =IF('Control 4'!$I$29="X",'Control 4'!$G$29," ") | I8: =IF('Control 5'!$I$29="X",'Control 5'!$G$29," ")
E9: =IF('Control 1'!$K$29="X",'Control 1'!$J$29," ") | F9: =IF('Control 2'!$K$29="X",'Control 2'!$J$29," ") -> Detective | G9: =IF('Control 3'!$K$29="X",'Control 3'!$J$29," ") | H9: =IF('Control 4'!$K$29="X",'Control 4'!$J$29," ") -> Detective | I9: =IF('Control 5'!$K$29="X",'Control 5'!$J$29," ") -> Detective
C10: Type | E10: =IF('Control 1'!$I$31="X",'Control 1'!$G$31," ") -> Verifications | F10: =IF('Control 2'!$I$31="X",'Control 2'!$G$31," ") | G10: =IF('Control 3'!$I$31="X",'Control 3'!$G$31," ") | H10: =IF('Control 4'!$I$31="X",'Control 4'!$G$31," ") | I10: =IF('Control 5'!$I$31="X",'Control 5'!$G$31," ")
E11: =IF('Control 1'!$K$31="X",'Control 1'!$J$31," ") | F11: =IF('Control 2'!$K$31="X",'Control 2'!$J$31," ") -> Controls over IUC | G11: =IF('Control 3'!$K$31="X",'Control 3'!$J$31," ") | H11: =IF('Control 4'!$K$31="X",'Control 4'!$J$31," ") | I11: =IF('Control 5'!$K$31="X",'Control 5'!$J$31," ")
E12: =IF('Control 1'!$I$32="X",'Control 1'!$G$32," ") | F12: =IF('Control 2'!$I$32="X",'Control 2'!$G$32," ") | G12: =IF('Control 3'!$I$32="X",'Control 3'!$G$32," ") -> Physical Controls and Counts | H12: =IF('Control 4'!$I$32="X",'Control 4'!$G$32," ") | I12: =IF('Control 5'!$I$32="X",'Control 5'!$G$32," ")
E13: =IF('Control 1'!$K$32="X",'Control 1'!$J$32," ") | F13: =IF('Control 2'!$K$32="X",'Control 2'!$J$32," ") | G13: =IF('Control 3'!$K$32="X",'Control 3'!$J$32," ") | H13: =IF('Control 4'!$K$32="X",'Control 4'!$J$32," ") -> Reconciliations | I13: =IF('Control 5'!$K$32="X",'Control 5'!$J$32," ")
E14: =IF('Control 1'!$I$33="X",'Control 1'!$G$33," ") | F14: =IF('Control 2'!$I$33="X",'Control 2'!$G$33," ") | G14: =IF('Control 3'!$I$33="X",'Control 3'!$G$33," ") | H14: =IF('Control 4'!$I$33="X",'Control 4'!$G$33," ") | I14: =IF('Control 5'!$I$33="X",'Control 5'!$G$33," ") -> Authorizations and Approvals
E15: =IF('Control 1'!$K$33="X",'Control 1'!$J$33," ") | F15: =IF('Control 2'!$K$33="X",'Control 2'!$J$33," ") | G15: =IF('Control 3'!$K$33="X",'Control 3'!$J$33," ") | H15: =IF('Control 4'!$K$33="X",'Control 4'!$J$33," ") | I15: =IF('Control 5'!$K$33="X",'Control 5'!$J$33," ") -> Controls with a Review Element
C16: Design Effectiveness Testing Conclusion | E16: ='Control 1'!$C$125 -> Effective | F16: ='Control 2'!$C$125 -> Effective | G16: ='Control 3'!$C$125 -> Effective | H16: ='Control 4'!$C$125 -> Effective | I16: ='Control 5'!$C$125 -> Effective
C18: Test of Operating Effectiveness
C19: Nature of Procedures: | E19: See Nature of Procedures on each individual tab | F19: See Nature of Procedures on each individual tab | G19: See Nature of Procedures on each individual tab | H19: See Nature of Procedures on each individual tab | I19: See Nature of Procedures on each individual tab
C20: Timing of Procedures | E20: ='Control 1'!$C$162 -> Interim/Rollforward | F20: ='Control 2'!$C$162 -> Interim/Rollforward | G20: ='Control 3'!$C$162 -> Interim/Rollforward | H20: ='Control 4'!$C$162 -> Interim/Rollforward | I20: ='Control 5'!$C$162 -> Interim/Rollforward
C21: Extent of Procedures: Number of Testing Selections | E21: ='Control 1'!$C$173 -> 2 | F21: ='Control 2'!$C$173 -> 2 | G21: ='Control 3'!$C$173 -> 2 | H21: ='Control 4'!$C$173 -> 2 | I21: ='Control 5'!$C$173 -> 2
C23: Number of Times the Control Operates per Year | E23: ='Control 1'!$C$172 -> 4 | F23: ='Control 2'!$C$172 -> 4 | G23: ='Control 3'!$C$172 -> 4 | H23: ='Control 4'!$C$172 -> 4 | I23: ='Control 5'!$C$172 -> 4
C24: Use of Work of Others (UWOO) | E24: ='Control 1'!$C$184 -> No | F24: ='Control 2'!$C$184 -> No | G24: ='Control 3'!$C$184 -> No | H24: ='Control 4'!$C$184 -> No | I24: ='Control 5'!$C$184 -> No
C25: Approach to Testing Work Performed by Others | E25: ='Control 1'!$C$186 -> N/A | F25: ='Control 2'!$C$186 -> N/A | G25: ='Control 3'!$C$186 -> N/A | H25: ='Control 4'!$C$186 -> N/A | I25: ='Control 5'!$C$186 -> N/A
C26: Rollforward (applicable when testing and concluding as of an interim date)
C27: Length of Rollforward Period | E27: =IF(E20="Apportion"," ",'Control 1'!$C$190) -> 0 | F27: =IF(F20="Apportion"," ",'Control 2'!$C$190) -> 0 | G27: =IF(G20="Apportion"," ",'Control 3'!$C$190) -> 0 | H27: =IF(H20="Apportion"," ",'Control 4'!$C$190) -> 0 | I27: =IF(I20="Apportion"," ",'Control 5'!$C$190) -> 0
C28: Nature of Procedures: | E28: See Nature of Procedures on each individual tab | F28: See Nature of Procedures on each individual tab | G28: See Nature of Procedures on each individual tab | H28: See Nature of Procedures on each individual tab | I28: See Nature of Procedures on each individual tab
C29: Timing of Procedures | E29: =IF(E20="Apportion"," ",'Control 1'!$C$195) -> 0 | F29: =IF(F20="Apportion"," ",'Control 2'!$C$195) -> 0 | G29: =IF(G20="Apportion"," ",'Control 3'!$C$195) -> 0 | H29: =IF(H20="Apportion"," ",'Control 4'!$C$195) -> 0 | I29: =IF(I20="Apportion"," ",'Control 5'!$C$195) -> 0
C30: Extent of Procedures: Number of Testing Selections | E30: =IF(E20="Apportion"," ",'Control 1'!$C$205) -> 1 | F30: =IF(F20="Apportion"," ",'Control 2'!$C$205) -> 1 | G30: =IF(G20="Apportion"," ",'Control 3'!$C$205) -> 1 | H30: =IF(H20="Apportion"," ",'Control 4'!$C$205) -> 1 | I30: =IF(I20="Apportion"," ",'Control 5'!$C$205) -> 1
C31: Use of Work of Others (UWOO) | E31: =IF(E20="Apportion"," ",'Control 1'!$C$216) -> No | F31: =IF(F20="Apportion"," ",'Control 2'!$C$216) -> No | G31: =IF(G20="Apportion"," ",'Control 3'!$C$216) -> No | H31: =IF(H20="Apportion"," ",'Control 4'!$C$216) -> No | I31: =IF(I20="Apportion"," ",'Control 5'!$C$216) -> No
C32: Approach to Testing Work Performed by Others | E32: =IF('Control 1'!$C$218=0," ",'Control 1'!$C$218) | F32: =IF('Control 2'!$C$218=0," ",'Control 2'!$C$218) | G32: =IF('Control 3'!$C$218=0," ",'Control 3'!$C$218) | H32: =IF('Control 4'!$C$218=0," ",'Control 4'!$C$218) | I32: =IF('Control 5'!$C$218=0," ",'Control 5'!$C$218)
B33: Conclusion
C35: Conclusion | E35: ='Control 1'!$C$252 -> Effective | F35: ='Control 2'!$C$252 -> Effective | G35: ='Control 3'!$C$252 -> Effective | H35: ='Control 4'!$C$252 -> Effective | I35: ='Control 5'!$C$252 -> Effective

Sheet Control 1
B2: Control Summary
B4: Control ID | C4: Control 1
B6: Control Activity —
B7: Summary Description
A10: =Notes!B4 -> Note 1 | B10: Control Description — Detailed Description of How the Control Is Expected to Be Performed | C10: Inputs Used by Reviewer:
C13: Specific Activities Performed by Reviewer (Steps of the Review):
C14: Step 1:
C16: Step 2:
C18: Step 3:
C20: Step 4:
C22: Step 5:
C24: Outputs of the Control:
A26: =Notes!$B$6 -> Note 2
B27: Nature, Approach, and Type | C27: Nature | G27: Manual | I27: X | J27: Automated
C29: Approach | G29: Preventive | I29: X | J29: Detective
C31: Type | G31: Verifications | I31: X | J31: Controls over IUC
G32: Physical Controls and Counts | J32: Reconciliations
G33: Authorizations and Approvals | J33: Controls with a Review Element
A35: =Notes!B8 -> Note 3 | B35: Risk(s) of Material Misstatement Addressed | C35: Risk 1 Addressed by the Control:
C36: RoMM Classification: | H36: Lower
C38: Risk 2 Addressed by the Control:
C39: RoMM Classification: | H39: Lower
B41: Significant Account(s) and Related Assertion(s) Addressed
B46: Test and Evaluation of Control Design
A48: =Notes!B10 -> Note 4 | B48: Procedures Performed to Test the Design of the Control | C48: Test of Design for Each Step of the Review
C50: Step 1: | H50: Inquiry | J50: Observation | L50: Inspection
C53: Step 2: | H53: Inquiry | J53: Observation | L53: Inspection
C56: Step 3: | H56: Inquiry | J56: Observation | L56: Inspection
C59: Step 4: | H59: Inquiry | J59: Observation | L59: Inspection
C62: Step 5: | H62: Inquiry | J62: Observation | L62: Inspection
B65: Design Factor 1: | C65: Appropriateness of the Purpose of the Control and Its Correlation to the Risk/Assertion
B66: Document considerations of the appropriateness of the purpose of the control and correlation to the risk/assertion identified in the RoMM | C66: Risk 1 Addressed by the Control:
B67: =Notes!B12 -> Note 5
C68: Risk 2 Addressed by the Control:
B70: Design Factor 2: | C70: Competence and Authority of the Person(s) Performing the Control
B71: Control Owner(s)
B73: Document considerations of the appropriateness of competence and authority of the person(s) performing the control
B82: Design Factor 3: | C82: Frequency and Consistency with Which the Control Is Performed
B83: Document considerations of how the frequency and consistency of operation of the control are appropriate
B88: Design Factor 4: | C88: Level of Aggregation and Predictability
...

Sheet Control 2
B2: Control Summary
B4: Control ID | C4: Control 2
B6: Control Activity —
B7: Summary Description
A10: =Notes!B4 -> Note 1 | B10: Control Description — Detailed Description of How the Control Is Expected to Be Performed | C10: Inputs Used by Reviewer:
C13: Specific Activities Performed by Reviewer (Steps of the Review):
C14: Step 1:
C16: Step 2:
C18: Step 3:
C20: Step 4:
C22: Step 5:
C24: Outputs of the Control:
A26: =Notes!$B$6 -> Note 2
B27: Nature, Approach, and Type | C27: Nature | G27: Manual | J27: Automated | K27: X
C29: Approach | G29: Preventive | J29: Detective | K29: X
C31: Type | G31: Verifications | J31: Controls over IUC | K31: X
G32: Physical Controls and Counts | J32: Reconciliations
G33: Authorizations and Approvals | J33: Controls with a Review Element
A35: =Notes!B8 -> Note 3 | B35: Risk(s) of Material Misstatement Addressed | C35: Risk 1 Addressed by the Control:
C36: RoMM Classification: | H36: Lower
C38: Risk 2 Addressed by the Control:
C39: RoMM Classification: | H39: Lower
B41: Significant Account(s) and Related Assertion(s) Addressed
B46: Test and Evaluation of Control Design
A48: =Notes!B10 -> Note 4 | B48: Procedures Performed to Test the Design of the Control | C48: Test of Design for Each Step of the Review
C50: Step 1: | H50: Inquiry | J50: Observation | L50: Inspection
C53: Step 2: | H53: Inquiry | J53: Observation | L53: Inspection
C56: Step 3: | H56: Inquiry | J56: Observation | L56: Inspection
C59: Step 4: | H59: Inquiry | J59: Observation | L59: Inspection
C62: Step 5: | H62: Inquiry | J62: Observation | L62: Inspection
B65: Design Factor 1: | C65: Appropriateness of the Purpose of the Control and Its Correlation to the Risk/Assertion
B66: Document considerations of the appropriateness of the purpose of the control and correlation to the risk/assertion identified in the RoMM | C66: Risk 1 Addressed by the Control:
B67: =Notes!B12 -> Note 5
C68: Risk 2 Addressed by the Control:
B70: Design Factor 2: | C70: Competence and Authority of the Person(s) Performing the Control
B71: Control Owner(s)
B73: Document considerations of the appropriateness of competence and authority of the person(s) performing the control
B82: Design Factor 3: | C82: Frequency and Consistency with Which the Control Is Performed
B83: Document considerations of how the frequency and consistency of operation of the control are appropriate
B88: Design Factor 4: | C88: Level of Aggregation and Predictability
...

Sheet Control 3
B2: Control Summary
B4: Control ID | C4: Control 3
B6: Control Activity —
B7: Summary Description
A10: =Notes!B4 -> Note 1 | B10: Control Description — Detailed Description of How the Control Is Expected to Be Performed | C10: Inputs Used by Reviewer:
C13: Specific Activities Performed by Reviewer (Steps of the Review):
C14: Step 1:
C16: Step 2:
C18: Step 3:
C20: Step 4:
C22: Step 5:
C24: Outputs of the Control:
A26: =Notes!$B$6 -> Note 2
B27: Nature, Approach, and Type | C27: Nature | G27: Manual | J27: Automated | K27: X
C29: Approach | G29: Preventive | I29: X | J29: Detective
C31: Type | G31: Verifications | J31: Controls over IUC
G32: Physical Controls and Counts | I32: X | J32: Reconciliations
G33: Authorizations and Approvals | J33: Controls with a Review Element
A35: =Notes!B8 -> Note 3 | B35: Risk(s) of Material Misstatement Addressed | C35: Risk 1 Addressed by the Control:
C36: RoMM Classification: | H36: Lower
C38: Risk 2 Addressed by the Control:
C39: RoMM Classification: | H39: Lower
B41: Significant Account(s) and Related Assertion(s) Addressed
B46: Test and Evaluation of Control Design
A48: =Notes!B10 -> Note 4 | B48: Procedures Performed to Test the Design of the Control | C48: Test of Design for Each Step of the Review
C50: Step 1: | H50: Inquiry | J50: Observation | L50: Inspection
C53: Step 2: | H53: Inquiry | J53: Observation | L53: Inspection
C56: Step 3: | H56: Inquiry | J56: Observation | L56: Inspection
C59: Step 4: | H59: Inquiry | J59: Observation | L59: Inspection
C62: Step 5: | H62: Inquiry | J62: Observation | L62: Inspection
B65: Design Factor 1: | C65: Appropriateness of the Purpose of the Control and Its Correlation to the Risk/Assertion
B66: Document considerations of the appropriateness of the purpose of the control and correlation to the risk/assertion identified in the RoMM | C66: Risk 1 Addressed by the Control:
B67: =Notes!B12 -> Note 5
C68: Risk 2 Addressed by the Control:
B70: Design Factor 2: | C70: Competence and Authority of the Person(s) Performing the Control
B71: Control Owner(s)
B73: Document considerations of the appropriateness of competence and authority of the person(s) performing the control
B82: Design Factor 3: | C82: Frequency and Consistency with Which the Control Is Performed
B83: Document considerations of how the frequency and consistency of operation of the control are appropriate
B88: Design Factor 4: | C88: Level of Aggregation and Predictability
...

Sheet Control 4
B2: Control Summary
B4: Control ID | C4: Control 4
B6: Control Activity —
B7: Summary Description
A10: =Notes!B4 -> Note 1 | B10: Control Description — Detailed Description of How the Control Is Expected to Be Performed | C10: Inputs Used by Reviewer:
C13: Specific Activities Performed by Reviewer (Steps of the Review):
C14: Step 1:
C16: Step 2:
C18: Step 3:
C20: Step 4:
C22: Step 5:
C24: Outputs of the Control:
A26: =Notes!$B$6 -> Note 2
B27: Nature, Approach, and Type | C27: Nature | G27: Manual | J27: Automated | K27: X
C29: Approach | G29: Preventive | J29: Detective | K29: X
C31: Type | G31: Verifications | J31: Controls over IUC
G32: Physical Controls and Counts | J32: Reconciliations | K32: X
G33: Authorizations and Approvals | J33: Controls with a Review Element
A35: =Notes!B8 -> Note 3 | B35: Risk(s) of Material Misstatement Addressed | C35: Risk 1 Addressed by the Control:
C36: RoMM Classification: | H36: Lower
C38: Risk 2 Addressed by the Control:
C39: RoMM Classification: | H39: Lower
B41: Significant Account(s) and Related Assertion(s) Addressed
B46: Test and Evaluation of Control Design
A48: =Notes!B10 -> Note 4 | B48: Procedures Performed to Test the Design of the Control | C48: Test of Design for Each Step of the Review
C50: Step 1: | H50: Inquiry | J50: Observation | L50: Inspection
C53: Step 2: | H53: Inquiry | J53: Observation | L53: Inspection
C56: Step 3: | H56: Inquiry | J56: Observation | L56: Inspection
C59: Step 4: | H59: Inquiry | J59: Observation | L59: Inspection
C62: Step 5: | H62: Inquiry | J62: Observation | L62: Inspection
B65: Design Factor 1: | C65: Appropriateness of the Purpose of the Control and Its Correlation to the Risk/Assertion
B66: Document considerations of the appropriateness of the purpose of the control and correlation to the risk/assertion identified in the RoMM | C66: Risk 1 Addressed by the Control:
B67: =Notes!B12 -> Note 5
C68: Risk 2 Addressed by the Control:
B70: Design Factor 2: | C70: Competence and Authority of the Person(s) Performing the Control
B71: Control Owner(s)
B73: Document considerations of the appropriateness of competence and authority of the person(s) performing the control
B82: Design Factor 3: | C82: Frequency and Consistency with Which the Control Is Performed
B83: Document considerations of how the frequency and consistency of operation of the control are appropriate
B88: Design Factor 4: | C88: Level of Aggregation and Predictability
...

Sheet Control 5
B2: Control Summary
B4: Control ID | C4: Control 5
B6: Control Activity —
B7: Summary Description
A10: =Notes!B4 -> Note 1 | B10: Control Description — Detailed Description of How the Control Is Expected to Be Performed | C10: Inputs Used by Reviewer:
C13: Specific Activities Performed by Reviewer (Steps of the Review):
C14: Step 1:
C16: Step 2:
C18: Step 3:
C20: Step 4:
C22: Step 5:
C24: Outputs of the Control:
A26: =Notes!$B$6 -> Note 2
B27: Nature, Approach, and Type | C27: Nature | G27: Manual | I27: X | J27: Automated
C29: Approach | G29: Preventive | J29: Detective | K29: X
C31: Type | G31: Verifications | J31: Controls over IUC
G32: Physical Controls and Counts | J32: Reconciliations
G33: Authorizations and Approvals | I33: X | J33: Controls with a Review Element | K33: X
A35: =Notes!B8 -> Note 3 | B35: Risk(s) of Material Misstatement Addressed | C35: Risk 1 Addressed by the Control:
C36: RoMM Classification: | H36: Lower
C38: Risk 2 Addressed by the Control:
C39: RoMM Classification: | H39: Lower
B41: Significant Account(s) and Related Assertion(s) Addressed
B46: Test and Evaluation of Control Design
A48: =Notes!B10 -> Note 4 | B48: Procedures Performed to Test the Design of the Control | C48: Test of Design for Each Step of the Review
C50: Step 1: | H50: Inquiry | J50: Observation | L50: Inspection
C53: Step 2: | H53: Inquiry | J53: Observation | L53: Inspection
C56: Step 3: | H56: Inquiry | J56: Observation | L56: Inspection
C59: Step 4: | H59: Inquiry | J59: Observation | L59: Inspection
C62: Step 5: | H62: Inquiry | J62: Observation | L62: Inspection
B65: Design Factor 1: | C65: Appropriateness of the Purpose of the Control and Its Correlation to the Risk/Assertion
B66: Document considerations of the appropriateness of the purpose of the control and correlation to the risk/assertion identified in the RoMM | C66: Risk 1 Addressed by the Control:
B67: =Notes!B12 -> Note 5
C68: Risk 2 Addressed by the Control:
B70: Design Factor 2: | C70: Competence and Authority of the Person(s) Performing the Control
B71: Control Owner(s)
B73: Document considerations of the appropriateness of competence and authority of the person(s) performing the control
B82: Design Factor 3: | C82: Frequency and Consistency with Which the Control Is Performed
B83: Document considerations of how the frequency and consistency of operation of the control are appropriate
B88: Design Factor 4: | C88: Level of Aggregation and Predictability
...

Sheet Template
B2: Control Summary
B4: Control ID
B6: Control Activity —
B7: Summary Description
A10: =Notes!B4 -> Note 1 | B10: Control Description — Detailed Description of How the Control Is Expected to Be Performed | C10: Inputs Used by Reviewer:
C13: Specific Activities Performed by Reviewer (Steps of the Review):
C14: Step 1:
C16: Step 2:
C18: Step 3:
C20: Step 4:
C22: Step 5:
C24: Outputs of the Control:
A26: =Notes!$B$6 -> Note 2
B27: Nature, Approach, and Type | C27: Nature | G27: Manual | J27: Automated
C29: Approach | G29: Preventive | J29: Detective
C31: Type | G31: Verifications | J31: Controls over IUC
G32: Physical Controls and Counts | J32: Reconciliations
G33: Authorizations and Approvals | J33: Controls with a Review Element
A35: =Notes!B8 -> Note 3 | B35: Risk(s) of Material Misstatement Addressed | C35: Risk 1 Addressed by the Control:
C36: RoMM Classification: | H36: Lower
C38: Risk 2 Addressed by the Control:
C39: RoMM Classification: | H39: Lower
B41: Significant Account(s) and Related Assertion(s) Addressed
B46: Test and Evaluation of Control Design
A48: =Notes!B10 -> Note 4 | B48: Procedures Performed to Test the Design of the Control | C48: Test of Design for Each Step of the Review
C50: Step 1: | H50: Inquiry | J50: Observation | L50: Inspection
C53: Step 2: | H53: Inquiry | J53: Observation | L53: Inspection
C56: Step 3: | H56: Inquiry | J56: Observation | L56: Inspection
C59: Step 4: | H59: Inquiry | J59: Observation | L59: Inspection
C62: Step 5: | H62: Inquiry | J62: Observation | L62: Inspection
B65: Design Factor 1: | C65: Appropriateness of the Purpose of the Control and Its Correlation to the Risk/Assertion
B66: Document considerations of the appropriateness of the purpose of the control and correlation to the risk/assertion identified in the RoMM | C66: Risk 1 Addressed by the Control:
B67: =Notes!B12 -> Note 5
C68: Risk 2 Addressed by the Control:
B70: Design Factor 2: | C70: Competence and Authority of the Person(s) Performing the Control
B71: Control Owner(s)
B73: Document considerations of the appropriateness of competence and authority of the person(s) performing the control
B82: Design Factor 3: | C82: Frequency and Consistency with Which the Control Is Performed
B83: Document considerations of how the frequency and consistency of operation of the control are appropriate
B88: Design Factor 4: | C88: Level of Aggregation and Predictability
...

Sheet Notes
B2: NOTES
B4: Note 1 | C4: Detailed Description of the Control Depending on the nature and complexity of the control, consider documenting the following: Inputs Used by the Control Performer: We understand and assess the information or reports (which we refer to as IUC) that are used in the performance of the control, including the process by which the information is generated. (Refer to Public Entity Internal Control Guide Section 9.3.1.) Specific Activities the Control Performer Is Performing: We document each relevant step of the control performer's activities to perform the control separately. (Refer to Public Entity Internal Control Guide Section 9.3.2.) Outputs of the Control: We also understand the outputs of the control, which includes understanding the specific evidence that supports that the control activity actually occurred. (Refer to Public Entity Internal Control Guide Section 9.3.3.)
B6: Note 2 | C6: Nature, Approach, and Type Controls may vary due to the nature, approach, and type of the control implemented by the entity to address a risk of material misstatement. Differences in the nature, approach, and type of a control result in an individual control being more or less reliable, and affect: • Procedures performed and timing of testing necessary to support our test and evaluation of design of a control. • Our determination of the risk associated with the control (see Note 10 for guidance on risk associated with the control). We consider the following characteristics when identifying relevant controls: • Nature: The nature of how the control is performed • Manual: Controls performed manually, not through technology. • Automated: Control activities wholly performed through technology (e.g., automated control functions programmed into computer software). • Approach: The approach management implemented to address the assessed risks • Preventive: Controls that have the objective of preventing errors or fraud that could result in a misstatement of the financial statements from occurring. • Detective: Controls that have the objective of detecting errors or fraud that has already occurred that could result in a misstatement of the financial statements. • Type: The type of control activity being performed • Verifications: Compare two or more items with each other or compare an item with a policy, and perform a follow-up action when the two items do not match or the item is not consistent with policy. • Authorization and Approvals: An authorization affirms that a transaction is valid (i.e., it represents an actual economic event or is within an entity’s policy). An authorization typically takes the form of an approval by higher level management or a determination that the transaction is valid. • Physical Controls and Counts: Equipment, inventories, securities, cash, and other assets are secured physically (e.g., locked or guarded storage areas with physical access restricted to authorized personnel) and are periodically counted and compared with amounts shown on control records. • Controls over IUC: Control activities over the processes to populate, update, and maintain the accuracy, completeness, and validity of IUC so that it is sufficiently reliable for its purpose. • Reconciliations: Compare two or more data elements and, if differences are identified, take action to bring data into agreement. • Controls with a Review Element (CREs): Controls with a review element are the controls management has over the reviews conducted by management or others of estimates and other kinds of financial information for reasonableness. They require judgment, knowledge, and experience. These reviews typically involve comparing recorded amounts with expectations of the reviewers based on their knowledge and experience. The reviewer’s knowledge is, in part, based on history and, in part, may depend upon examining reports and underlying documents. Consider if the control represents a series of controls; if so, clearly identify the nature, approach, and type of the control by selecting the nature, approach, and type in the checkboxes provided. (Refer to Public Entity Internal Control Guide Section 2.4.)
B8: Note 3 | C8: Risk(s) of Material Misstatement Addressed Document each risk of material misstatement that the control addresses. Engagement teams may add/delete rows based on number of risks of material misstatement addressed by the control. Engagement teams should document the full risk of material misstatement text here and not just the risk of material misstatement reference number.
B10: Note 4 | C10: Test and Evaluation of Control Design Utilize this section to document the nature of the procedures performed (e.g., inquiry, observation, inspection of documentation, or some combination thereof) and use the free text section to describe the procedures performed. (Refer to Public Entity Internal Control Guide Sections 2.5 and 9.4.) For the applicable Design Factors, document our considerations and evaluation of the precision of the control to effectively address the risks of material misstatement identified (Refer to Public Entity Internal Control Guide Sections 2.5.1 and 9.4.)
B12: Note 5 | C12: Design Factor 1: Appropriateness of the Purpose of the Control and Its Correlation to the Risk/Assertion For each risk of material misstatement documented in the “Risk(s) of Material Misstatement Addressed” documentation boxes, we document how the control addresses each of the risks of material misstatement as well as the related assertion(s). If the control addresses more than one risk of material misstatement, add additional rows for each risk of material misstatement identified. If this control alone does not address the risk of material misstatement and related assertion(s), document which other control(s) in combination with this control addresses the risk of material misstatement and related assertion(s), where that control(s) is tested as well as the conclusion on the design and operating effectiveness of that control(s). For example, “As indicated within working paper XXXX, this control is designed and implemented, and, as applicable, operates in concert with other controls [indicate specific controls] to address the identified risk of material misstatement and assertions noted above. See evaluation of design, determination of implementation, and where applicable, tests of operating effectiveness of these controls at working paper XXXX. Based on our evaluation of design, determination of implementation, and where applicable, tests of operating effectiveness of these controls we concluded they are designed, implemented, and, as applicable, operating effectively.”
B14: Note 6 | C14: Design Factor 5: Criteria for Investigation (i.e., threshold) and Process for Follow-up The threshold for investigating deviations or differences and its relationship to materiality is an important but subjective determination of a control’s precision. It is equally important that there is an appropriate process to follow up on any exceptions or unusual items noted from the review, including tracking open items for timely resolution and determining that responses are appropriate and supported as necessary (e.g., further review and challenge by others). (Refer to Public Entity Internal Control Guide Section 9.4.) The threshold for investigating deviations or differences from expectations relative to materiality is an indication of a control's precision. For example, a control that investigates items that are near the threshold for financial statement materiality has less precision and a greater risk of failing to prevent or detect misstatements that could be material than a control with a lower threshold for investigation. (Refer to Public Entity Internal Control Guide Section 9.4.) The documentation of the criteria for investigation for follow-up may be documented within the control description for the applicable step or in the space provided for design factor 5.
B16: Note 7 | C16: Dependency of the Control on IUC When the effectiveness of a control is dependent upon IUC (and the effectiveness of the control is therefore dependent on the accuracy and completeness of such information), utilize this section to reference where the controls that address the accuracy and completeness are tested (including the source data, report logic, and parameters). In addition, utilize this space to document the conclusions reached as a result of the testing referenced. See PCAOB AAM 13300.25 for the requirements related to testing the accuracy and completeness of IUC. (Refer to Public Entity Internal Control Guide Chapter 4.)
B18: Note 8 | C18: System-Generated IUC Utilize the space provided to document our testing over the completeness and accuracy of the IUC for System-Generated reports considering the guidance in the Public Entity Internal Control Guide Section 4.5.1.
B20: Note 9 | C20: Non-System-Generated IUC Utilize the space provided to document our testing over the completeness and accuracy of the IUC for Non-System-Generated reports considering the guidance in the Public Entity Internal Control Guide Section 4.5.1.
B22: Note 10 | C22: Risk Associated with the Control Utilize the space provided to document those considerations relevant to the conclusion reached (Refer to Public Entity Internal Control Guide Section 3.4.)
B24: Note 11 | C24: Planned Nature of Operating Effectiveness Testing Utilize this section to document the nature of the procedures (regardless of whether we are performing the testing ourselves or using the work of others) that will be performed (e.g., inquiry, observation, inspection of documentation, reperformance, or some combination thereof) in the checkboxes provided, and use the free text section to describe the procedures to be performed. We typically perform a combination of procedures to obtain evidence of whether a control that addresses a significant risk is operating effectively, as more persuasive evidence is often needed (Refer to Public Entity Internal Control Guide Sections 3.5.1 and 9.5.)
B26: Note 12 | C26: Planned Timing of Operating Effectiveness Testing Utilize this section to document the period to be covered by the testing (regardless of whether we are performing the testing ourselves or using the work of others) by using the dropdown box (i.e., whether the sample will be apportioned over the full year or the full sample will be tested at an interim period), and use the free text box to document any other relevant considerations (Refer to Public Entity Internal Control Guide Section 3.5.2).
... B38: Note 18 | C38: Exception or Deviation Utilize this section to document whether any deviations were identified (Refer to Public Entity Internal Control Guide Section 3.8.).
Q176: Not a Higher Risk Associated with the Control – Normal Extent of Testing

Sheet Data Field
A1: X
